<?xml version="1.0" ?>
<robot name="my_robot">

    <link name="base_link">
        <visual>
            <origin xyz=" 0 0 0" rpy="0 0 0" />
            <geometry>
                <box size="0.3 0.2 0.1" />
            </geometry>
            <material name="yellow">
                <color rgba="1 0.4 0 1"/>
            </material>
        </visual>

        <inertial>
            <mass value="5" />
            <origin xyz="0 0 0" />
            <inertia ixx="0.02083" ixy="0.00000" ixz="0.00000"
                     iyy="0.04166" iyz="0.00000" izz="0.05416" />
        </inertial>

        <collision>
            <origin xyz="0 0 0" rpy="0 0 0" />
            <geometry>
                <box size="0.3 0.2 0.1" />
            </geometry>            
        </collision>
    </link>

    <link name="front_left">
        <visual>
            <origin xyz=" 0 0 0" rpy="1.57 0 0" />
            <geometry>
                <cylinder radius="0.04" length = "0.04"/>
            </geometry>
            <material name="gray">
                <color rgba="0.75 0.75 0.75 1"/>
            </material>
        </visual>

        <inertial>
            <mass value="1" />
            <origin xyz="0 0 0" />
            <inertia ixx="0.00053" ixy="0.00000" ixz="0.00000"
                     iyy="0.00053" iyz="0.00000" izz="0.00080" />
        </inertial>

        <collision>
            <origin xyz="0 0 0" rpy="1.57 0 0" />
            <geometry>
                <cylinder radius="0.04" length = "0.04"/>
            </geometry>            
        </collision>        
    </link>    

    <link name="front_righ">
        <visual>
            <origin xyz=" 0 0 0" rpy="1.57 0 0" />
            <geometry>
                <cylinder radius="0.04" length = "0.04"/>
            </geometry>
            <material name="gray">
                <color rgba="0.75 0.75 0.75 1"/>
            </material>
        </visual>

        <inertial>
            <mass value="1" />
            <origin xyz="0 0 0" />
            <inertia ixx="0.00053" ixy="0.00000" ixz="0.00000"
                     iyy="0.00053" iyz="0.00000" izz="0.00080" />
        </inertial>

        <collision>
            <origin xyz="0 0 0" rpy="1.57 0 0" />
            <geometry>
                <cylinder radius="0.04" length = "0.04"/>
            </geometry>            
        </collision>             
    </link>   

    <link name="back_left">
        <visual>
            <origin xyz=" 0 0 0" rpy="1.57 0 0" />
            <geometry>
                <cylinder radius="0.04" length = "0.04"/>
            </geometry>
            <material name="gray">
                <color rgba="0.75 0.75 0.75 1"/>
            </material>
        </visual>

        <inertial>
            <mass value="1" />
            <origin xyz="0 0 0" />
            <inertia ixx="0.00053" ixy="0.00000" ixz="0.00000"
                     iyy="0.00053" iyz="0.00000" izz="0.00080" />
        </inertial>

        <collision>
            <origin xyz="0 0 0" rpy="1.57 0 0" />
            <geometry>
                <cylinder radius="0.04" length = "0.04"/>
            </geometry>            
        </collision>             
    </link>    

    <link name="back_righ">
        <visual>
            <origin xyz=" 0 0 0" rpy="1.57 0 0" />
            <geometry>
                <cylinder radius="0.04" length = "0.04"/>
            </geometry>
            <material name="gray">
                <color rgba="0.75 0.75 0.75 1"/>
            </material>
        </visual>

        <inertial>
            <mass value="1" />
            <origin xyz="0 0 0" />
            <inertia ixx="0.00053" ixy="0.00000" ixz="0.00000"
                     iyy="0.00053" iyz="0.00000" izz="0.00080" />
        </inertial>

        <collision>
            <origin xyz="0 0 0" rpy="1.57 0 0" />
            <geometry>
                <cylinder radius="0.04" length = "0.04"/>
            </geometry>            
        </collision>      
    </link>       

    <joint name="front_left_joint" type="continuous">
        <origin xyz="0.15 0.12 -0.05" rpy="0 0 0"/>
        <parent link="base_link"/>
        <child link="front_left"/>
        <axis xyz="0 1 0"/>
    </joint>    

    <joint name="front_righ_joint" type="continuous">
        <origin xyz="0.15 -0.12 -0.05" rpy="0 0 0"/>
        <parent link="base_link"/>
        <child link="front_righ"/>
        <axis xyz="0 1 0"/>
    </joint>

    <joint name="back_left_joint" type="continuous">
        <origin xyz="-0.15 0.12 -0.05" rpy="0 0 0"/>
        <parent link="base_link"/>
        <child link="back_left"/>
        <axis xyz="0 1 0"/>
    </joint>    

    <joint name="back_righ_joint" type="continuous">
        <origin xyz="-0.15 -0.12 -0.05" rpy="0 0 0"/>
        <parent link="base_link"/>
        <child link="back_righ"/>
        <axis xyz="0 1 0"/>
    </joint>

</robot>